Workbook

Sheet Base de datos
A5: BASE DE DATOS DE CLIENTES
A7: No. | B7: PKA | C7: Apellidos | D7: Nombres | E7: Nombre Legal | F7: Grupo | G7: Fecha de Nacimiento | H7: Tipo de Servicio que le Brindamos | I7: Correo Electrónico | J7: Teléfono | K7: Artista | L7: Escritor | M7: Productor
A8: 1 | B8: Dayan | C8: Giler | D8: Dayan | E8: Dayan Giler | F8: X | I8: dayanmvpx@gmail.com | K8: X
A9: 2 | B9: Marval | C9: Marval Camero | D9: Luis Guillermo | E9: Luis Guillermo Marval Camero | F9: x | I9: Energymusicvzla@gmail.com | K9: X | L9: X
A10: =+A9+1 -> 3 | B10: Pantera | C10: Arteaga | D10: William | E10: William Arteaga | I10: williamjarteaga@gmail.com | L10: X
A11: =+A10+1 -> 4 | B11: Divino | C11: Velazquez | D11: Daniel | E11: Daniel Velazquez | K11: x
A12: =+A11+1 -> 5 | B12: Dimelo Super | C12: Perea Añez | D12: Jesus Alberto | E12: Jesus Alberto Perea Añez | F12: No | I12: dimelosuper@gmail.com | K12: ? | L12: ? | M12: ?
A13: =+A12+1 -> 6 | B13: SAINT LL | K13: x
A14: 7 | B14: Jordy Jill | C14: Valdivieso Duarte | D14: Jordy Camilo | E14: Jordy Camilo Valdivieso Duarte | I14: maribell.duarte@jordyjill.com | K14: x | L14: x
A15: =+A14+1 -> 8 | B15: Borngud | D15: Jhon Emanuel | E15: Jhon Emanuel | I15: borngud22@gmail.com | K15: x
A16: =+A15+1 -> 9 | B16: MaikyMove | C16: Sanchez | D16: Miguel Alejandro | E16: Miguel Alejandro Sanchez | I16: onlymaiky@gmail.com | K16: x
A17: =+A16+1 -> 10 | B17: Lanalizer | C17: Guzmán Velásquez | D17: Yan Carlo Francisco | E17: Yan Carlo Francisco Guzmán Velásquez | I17: lanalizerrecords@gmail.com | M17: x
A18: =+A17+1 -> 11 | B18: MozartMuzik | C18: Nizco Chaparro | D18: Jose Luis | E18: Jose Luis Nizco Chaparro | F18: x | I18: mozartmuzik2@gmail.com | M18: x
A19: =+A18+1 -> 12 | B19: Hache | C19: Taveras | D19: Bryan Argenis | E19: Bryan Argenis Taveras | I19: achebookings@gmail.com | K19: x | L19: x
A20: =+A19+1 -> 13 | B20: ErickAnt | C20: Celis Marin | D20: Erick Andres | E20: Erick Andres Celis Marin | F20: x | I20: Erickandrescm@gmail.com | M20: x
A21: 14 | B21: ECBY | C21: Campoverde | D21: Erick | E21: Erick Campoverde | F21: x | I21: contactoecby@gmail.com | M21: x
A22: 15 | B22: Jay Rozz | C22: Arias | D22: Juan | E22: Juan Arias | F22: x | I22: Jayrozzbooking@gmail.com | K22: x | L22: x
A23: =+A22+1 -> 16 | B23: Cubo | C23: Cuadrado | D23: Franklin | E23: Franklin Cuadrado | F23: x | I23: prodbycubo@gmail.com | M23: x
A24: =+A23+1 -> 17 | B24: Lennis Rodriguez | C24: Rodriguez | D24: Jorlennis | E24: Jorlennis Rodriguez | I24: info.lennis@gmail.com | K24: x

Sheet MODELO
B2: Artista:
B3: Nombre legal:
B4: Fecha de inicio: | E4: =MIN(Table1347[Fecha]) -> 0
B5: Fecha fin: | E5: =MAX(Table1347[Fecha]) -> 0
B7: ESTADO DE CUENTA
B8: Fecha | C8: Número | D8: Tipo | E8: Método de pago | F8: Nombre | G8: Concepto | H8: Valor de la Factura del Cliente | I8: Cargos Bancarios | J8: 50% Fee | K8: 20% Comisión | L8: 5% Legal | M8: Retención de Impuestos | N8: Pagado por MVPX | O8: Avance | P8: Balance
P9: =SUM(Table1347[[#This Row],[Valor de la Factura del Cliente]:[Avance]]) -> 0
P10: =SUM(Table1347[[#This Row],[Valor de la Factura del Cliente]:[Avance]])+P9 -> 0
P11: =SUM(Table1347[[#This Row],[Valor de la Factura del Cliente]:[Avance]])+P10 -> 0
P12: =SUM(Table1347[[#This Row],[Valor de la Factura del Cliente]:[Avance]])+P11 -> 0
P13: =SUM(Table1347[[#This Row],[Valor de la Factura del Cliente]:[Avance]])+P12 -> 0
P14: =SUM(Table1347[[#This Row],[Valor de la Factura del Cliente]:[Avance]])+P13 -> 0
P15: =SUM(Table1347[[#This Row],[Valor de la Factura del Cliente]:[Avance]])+P14 -> 0
P16: =SUM(Table1347[[#This Row],[Valor de la Factura del Cliente]:[Avance]])+P15 -> 0
P17: =SUM(Table1347[[#This Row],[Valor de la Factura del Cliente]:[Avance]])+P16 -> 0
P18: =SUM(Table1347[[#This Row],[Valor de la Factura del Cliente]:[Avance]])+P17 -> 0
P19: =SUM(Table1347[[#This Row],[Valor de la Factura del Cliente]:[Avance]])+P18 -> 0
P20: =SUM(Table1347[[#This Row],[Valor de la Factura del Cliente]:[Avance]])+P19 -> 0
P21: =SUM(Table1347[[#This Row],[Valor de la Factura del Cliente]:[Avance]])+P20 -> 0
... P38: =SUM(Table1347[[#This Row],[Valor de la Factura del Cliente]:[Avance]])+P37 -> 0
G39: TOTAL | H39: =SUBTOTAL(109,Table1347[Valor de la Factura del Cliente]) -> 0 | I39: =SUBTOTAL(109,Table1347[Cargos Bancarios]) -> 0 | K39: =SUBTOTAL(109,Table1347[20% Comisión]) -> 0 | L39: =SUBTOTAL(109,Table1347[5% Legal]) -> 0 | M39: =SUBTOTAL(109,Table1347[Retención de Impuestos]) -> 0 | N39: =SUBTOTAL(109,Table1347[Pagado por MVPX]) -> 0 | O39: =SUBTOTAL(109,Table1347[Avance]) -> 0 | P39: =+P38 -> 0

Sheet Jeidi
B2: Artista: | E2: Jeidi
B3: Nombre legal:
B4: Fecha de inicio: | E4: =MIN(Table134732[Fecha]) -> 45064
B5: Fecha fin: | E5: =MAX(Table134732[Fecha]) -> 45847
B7: ESTADO DE CUENTA
B8: Fecha | C8: Número | D8: Tipo | E8: Método de pago | F8: Nombre | G8: Concepto | H8: Valor de la Factura del Cliente | I8: Cargos Bancarios | J8: 50% Fee | K8: 20% Comisión | L8: 5% Legal | M8: Retención de Impuestos | N8: Pagado por MVPX | O8: Avance | P8: Balance
B9: Hasta el Q2 2024 BMI | G9: Ingresos de Bellakeo | H9: 23182 | N9: 0 | P9: =SUM(Table134732[[#This Row],[Valor de la Factura del Cliente]:[Avance]]) -> 23182
B10: 45064 | G10: Tema Loco si | N10: -333 | P10: =SUM(Table134732[[#This Row],[Valor de la Factura del Cliente]:[Avance]])+P9 -> 22849
B11: 45127 | G11: Avance | N11: -262.5 | P11: =SUM(Table134732[[#This Row],[Valor de la Factura del Cliente]:[Avance]])+P10 -> 22586.5
B12: 45128 | G12: Avance | N12: -700 | P12: =SUM(Table134732[[#This Row],[Valor de la Factura del Cliente]:[Avance]])+P11 -> 21886.5
B13: 45166 | G13: Avance | N13: -212.5 | P13: =SUM(Table134732[[#This Row],[Valor de la Factura del Cliente]:[Avance]])+P12 -> 21674
B14: 45170 | G14: Avance | N14: -230 | P14: =SUM(Table134732[[#This Row],[Valor de la Factura del Cliente]:[Avance]])+P13 -> 21444
B15: 45180 | G15: Avance | N15: -200 | P15: =SUM(Table134732[[#This Row],[Valor de la Factura del Cliente]:[Avance]])+P14 -> 21244
B16: 45187 | G16: Avance | N16: -100 | P16: =SUM(Table134732[[#This Row],[Valor de la Factura del Cliente]:[Avance]])+P15 -> 21144
B17: 45209 | G17: Avance | N17: -200 | P17: =SUM(Table134732[[#This Row],[Valor de la Factura del Cliente]:[Avance]])+P16 -> 20944
B18: 45209 | G18: Avance | N18: -100 | P18: =SUM(Table134732[[#This Row],[Valor de la Factura del Cliente]:[Avance]])+P17 -> 20844
B19: 45209 | G19: HECTOR NADIEL HURTADO | N19: -2000 | P19: =SUM(Table134732[[#This Row],[Valor de la Factura del Cliente]:[Avance]])+P18 -> 18844
B20: 45210 | G20: ELIAS AS YOUSEF | N20: -2000 | P20: =SUM(Table134732[[#This Row],[Valor de la Factura del Cliente]:[Avance]])+P19 -> 16844
B21: 45224 | G21: Avance (firma de jeidi) | N21: -3500 | P21: =SUM(Table134732[[#This Row],[Valor de la Factura del Cliente]:[Avance]])+P20 -> 13344
... B70: 45729 | G70: Elias Assy | N70: -100 | P70: =SUM(Table134732[[#This Row],[Valor de la Factura del Cliente]:[Avance]])+P69 -> -13716.36
B71: 45736 | G71: Pago de Contenido Autentico | H71: 400 | N71: 0 | P71: =SUM(Table134732[[#This Row],[Valor de la Factura del Cliente]:[Avance]])+P70 -> -13316.36
B72: 45740 | G72: Elias Assy | N72: -140 | P72: =SUM(Table134732[[#This Row],[Valor de la Factura del Cliente]:[Avance]])+P71 -> -13456.36
B73: 45740 | G73: Zenaida Duarte | N73: -260 | P73: =SUM(Table134732[[#This Row],[Valor de la Factura del Cliente]:[Avance]])+P72 -> -13716.36
B74: 45690 | G74: Airbnb on the Visa Expense | N74: -44.77 | P74: =SUM(Table134732[[#This Row],[Valor de la Factura del Cliente]:[Avance]])+P73 -> -13761.13
B75: 45804 | G75: Elias assy | N75: -450 | P75: =SUM(Table134732[[#This Row],[Valor de la Factura del Cliente]:[Avance]])+P74 -> -14211.13
B76: 45804 | G76: Pago en el Bofa | H76: 400 | N76: 0 | P76: =SUM(Table134732[[#This Row],[Valor de la Factura del Cliente]:[Avance]])+P75 -> -13811.13
B77: 45828 | G77: Wilman Henao | N77: -250 | P77: =SUM(Table134732[[#This Row],[Valor de la Factura del Cliente]:[Avance]])+P76 -> -14061.13
B78: 45831 | G78: Elias assy | N78: -250 | P78: =SUM(Table134732[[#This Row],[Valor de la Factura del Cliente]:[Avance]])+P77 -> -14311.13
B79: 45847 | G79: Michelle Flores | N79: -250 | P79: =SUM(Table134732[[#This Row],[Valor de la Factura del Cliente]:[Avance]])+P78 -> -14561.13
G80: TOTAL | H80: =SUBTOTAL(109,Table134732[Valor de la Factura del Cliente]) -> 23982 | I80: =SUBTOTAL(109,Table134732[Cargos Bancarios]) -> 0 | K80: =SUBTOTAL(109,Table134732[20% Comisión]) -> 0 | L80: =SUBTOTAL(109,Table134732[5% Legal]) -> 0 | M80: =SUBTOTAL(109,Table134732[Retención de Impuestos]) -> 0 | N80: =SUBTOTAL(109,Table134732[Pagado por MVPX]) -> -38543.13 | O80: =SUBTOTAL(109,Table134732[Avance]) -> 0 | P80: =+P79 -> -14561.13

Sheet Cesa Dajoy
B2: Artista: | E2: Cesar Dajoy
B3: Nombre legal:
B4: Fecha de inicio: | E4: =MIN(Table134731[Fecha]) -> 45657
B5: Fecha fin: | E5: =MAX(Table134731[Fecha]) -> 45771
B7: ESTADO DE CUENTA
B8: Fecha | C8: Número | D8: Tipo | E8: Método de pago | F8: Nombre | G8: Concepto | H8: Valor de la Factura del Cliente | I8: Cargos Bancarios | J8: 50% Fee | K8: 20% Comisión | L8: 5% Legal | M8: Retención de Impuestos | N8: Pagado por MVPX | O8: Avance | P8: Balance
B9: 45657 | F9: Ingrid Katherine | G9: Pagado a Ingrid Katherin Virviescas Valbuena por la Visa | N9: -345 | P9: =SUM(Table134731[[#This Row],[Valor de la Factura del Cliente]:[Avance]]) -> -345
B10: 45660 | F10: Wingo | G10: WINGO Gastos de Viaje | N10: -176.3 | P10: =SUM(Table134731[[#This Row],[Valor de la Factura del Cliente]:[Avance]])+P9 -> -521.3
B11: 45676 | F11: Avianca | G11: Vuelo MDE BOG | N11: -143.4 | P11: =SUM(Table134731[[#This Row],[Valor de la Factura del Cliente]:[Avance]])+P10 -> -664.7
B12: 45676 | F12: Expedia | G12: Travel Expense Hyaat Hotel Visa-CesarDajoy | N12: -63 | P12: =SUM(Table134731[[#This Row],[Valor de la Factura del Cliente]:[Avance]])+P11 -> -727.7
B13: 45686 | F13: Airbnb | G13: Pago de Airbnb Rozz, Jeidi, Dajoy | N13: -57.09 | P13: =SUM(Table134731[[#This Row],[Valor de la Factura del Cliente]:[Avance]])+P12 -> -784.79
B14: 45679 | F14: Airbnb | G14: Pago de Airbnb Rozz, Jeidi, Dajoy | N14: -100.80333 | P14: =SUM(Table134731[[#This Row],[Valor de la Factura del Cliente]:[Avance]])+P13 -> -885.59333
B15: 45690 | F15: Costco | G15: Pago de Comida Campamento PR | N15: -82.25 | P15: =SUM(Table134731[[#This Row],[Valor de la Factura del Cliente]:[Avance]])+P14 -> -967.84333
B16: 45690 | F16: Costco | G16: Pago de Comida Campamento PR | N16: -113.09 | P16: =SUM(Table134731[[#This Row],[Valor de la Factura del Cliente]:[Avance]])+P15 -> -1080.9333
B17: 45691 | F17: NewTasteChinese | G17: Pago de Comida Campamento PR | N17: -31.02 | P17: =SUM(Table134731[[#This Row],[Valor de la Factura del Cliente]:[Avance]])+P16 -> -1111.9533
B18: 45692 | F18: Costco | G18: Pago de Comida Campamento PR | N18: -62.66 | P18: =SUM(Table134731[[#This Row],[Valor de la Factura del Cliente]:[Avance]])+P17 -> -1174.6133
B19: 45690 | F19: Jetblue | G19: Boletos de Jet Blue | N19: -232.41 | P19: =SUM(Table134731[[#This Row],[Valor de la Factura del Cliente]:[Avance]])+P18 -> -1407.0233
B20: 45691 | F20: Jetblue | G20: Maletas de Jet Blue | N20: -70 | P20: =SUM(Table134731[[#This Row],[Valor de la Factura del Cliente]:[Avance]])+P19 -> -1477.0233
B21: 45692 | F21: Jetblue | G21: Boletos de Jet Blue | N21: -138.1 | P21: =SUM(Table134731[[#This Row],[Valor de la Factura del Cliente]:[Avance]])+P20 -> -1615.1233
... B27: 45690 | F27: Airbnb | G27: Airbnb Visa Appointment | N27: -44.77 | P27: =SUM(Table134731[[#This Row],[Valor de la Factura del Cliente]:[Avance]])+P26 -> -4788.3533
G28: TOTAL | H28: =SUBTOTAL(109,Table134731[Valor de la Factura del Cliente]) -> 0 | I28: =SUBTOTAL(109,Table134731[Cargos Bancarios]) -> 0 | K28: =SUBTOTAL(109,Table134731[20% Comisión]) -> 0 | L28: =SUBTOTAL(109,Table134731[5% Legal]) -> 0 | M28: =SUBTOTAL(109,Table134731[Retención de Impuestos]) -> 0 | N28: =SUBTOTAL(109,Table134731[Pagado por MVPX]) -> -4788.3533 | O28: =SUBTOTAL(109,Table134731[Avance]) -> 0 | P28: =+#REF! -> #REF!

Sheet ReneDaSilva
B2: Artista: | E2: Rene Da Silva
B3: Nombre legal:
B4: Fecha de inicio: | E4: =MIN(Table134730[Fecha]) -> 45676
B5: Fecha fin: | E5: =MAX(Table134730[Fecha]) -> 45819
B7: ESTADO DE CUENTA
B8: Fecha | C8: Número | D8: Tipo | E8: Método de pago | F8: Nombre | G8: Concepto | H8: Valor de la Factura del Cliente | I8: Cargos Bancarios | J8: 50% Fee | K8: 20% Comisión | L8: 5% Legal | M8: Retención de Impuestos | N8: Pagado por MVPX | O8: Avance | P8: Balance
B9: 45676 | F9: Avianca | G9: Vuelo Ida Y vuelta Colimbia Avianca | N9: 173.4 | P9: =SUM(Table134730[[#This Row],[Valor de la Factura del Cliente]:[Avance]]) -> 173.4
B10: 45677 | F10: Expedia | G10: Travel Expense Hyaat Hotel Visa- Rene Da Silva | N10: 89.76 | P10: =SUM(Table134730[[#This Row],[Valor de la Factura del Cliente]:[Avance]])+P9 -> 263.16
B11: 45697 | F11: COSTCO | G11: Gastos de Comida en Campamento PR | H11: 0 | N11: 82.25 | P11: =SUM(Table134730[[#This Row],[Valor de la Factura del Cliente]:[Avance]])+P10 -> 345.41
B12: 45703 | F12: COSTCO | G12: Gastos de Comida en Campamento PR | H12: 0 | N12: 113.09 | P12: =SUM(Table134730[[#This Row],[Valor de la Factura del Cliente]:[Avance]])+P11 -> 458.5
B13: 45690 | F13: JETBLUE | G13: Gastos de Transprte por Campamento | H13: 0 | N13: 232.41 | P13: =SUM(Table134730[[#This Row],[Valor de la Factura del Cliente]:[Avance]])+P12 -> 690.91
B14: 45690 | F14: JETBLUE | G14: Gastos de Transprte por Campamento | H14: 0 | N14: 138.1 | P14: =SUM(Table134730[[#This Row],[Valor de la Factura del Cliente]:[Avance]])+P13 -> 829.01
B15: 45691 | F15: NewTasteChinese | G15: Gastos de Comida en Campamento PR | H15: 0 | N15: 31.02 | P15: =SUM(Table134730[[#This Row],[Valor de la Factura del Cliente]:[Avance]])+P14 -> 860.03
B16: 45692 | F16: COSTCO | G16: Gastos de Comida en Campamento PR | H16: 0 | N16: 62.66 | P16: =SUM(Table134730[[#This Row],[Valor de la Factura del Cliente]:[Avance]])+P15 -> 922.69
B17: 45708 | F17: Spirit | G17: Vuelo SJU - FLL | N17: 150.99 | P17: =SUM(Table134730[[#This Row],[Valor de la Factura del Cliente]:[Avance]])+P16 -> 1073.68
B18: 45723 | F18: Tuyo | G18: Servicios de Producción de Tuyo - Marval | H18: -250 | N18: 0 | P18: =SUM(Table134730[[#This Row],[Valor de la Factura del Cliente]:[Avance]])+P17 -> 823.68
B19: 45733 | F19: Dynamic Records | G19: Ingreso Dynamic Records por la produccion del tema Mejor Que Tu | H19: -828.33333 | N19: 0 | P19: =SUM(Table134730[[#This Row],[Valor de la Factura del Cliente]:[Avance]])+P18 -> -4.6533333
B20: 45751 | F20: Iberia0151 | G20: Vuelo a Madrid-Medellin | H20: 0 | N20: 474.1 | P20: =SUM(Table134730[[#This Row],[Valor de la Factura del Cliente]:[Avance]])+P19 -> 469.44667
B21: 45760 | F21: Ryanair | G21: Vuelo Ibiza VLC | N21: 132.015 | P21: =SUM(Table134730[[#This Row],[Valor de la Factura del Cliente]:[Avance]])+P20 -> 601.46167
B22: 45819 | F22: DE TO | G22: Servicios de Producción de DE TO - Saint LL | H22: -300 | N22: 0 | P22: =SUM(Table134730[[#This Row],[Valor de la Factura del Cliente]:[Avance]])+P21 -> 301.46167
G23: TOTAL | H23: =SUBTOTAL(109,Table134730[Valor de la Factura del Cliente]) -> -1378.3333 | I23: =SUBTOTAL(109,Table134730[Cargos Bancarios]) -> 0 | K23: =SUBTOTAL(109,Table134730[20% Comisión]) -> 0 | L23: =SUBTOTAL(109,Table134730[5% Legal]) -> 0 | M23: =SUBTOTAL(109,Table134730[Retención de Impuestos]) -> 0 | N23: =SUBTOTAL(109,Table134730[Pagado por MVPX]) -> 1679.795 | O23: =SUBTOTAL(109,Table134730[Avance]) -> 0 | P23: =+#REF! -> #REF!

Sheet Jaime Hospedales
B2: Artista: | E2: Jaime Hospedales
B3: Nombre legal:
B4: Fecha de inicio: | E4: =MIN(Table134729[Fecha]) -> 45692
B5: Fecha fin: | E5: =MAX(Table134729[Fecha]) -> 45708
B7: ESTADO DE CUENTA
B8: Fecha | C8: Número | D8: Tipo | E8: Método de pago | F8: Nombre | G8: Concepto | H8: Valor de la Factura del Cliente | I8: Cargos Bancarios | J8: 50% Fee | K8: 20% Comisión | L8: 5% Legal | M8: Retención de Impuestos | N8: Pagado por MVPX | O8: Avance | P8: Balance
B9: 45697 | F9: COSTCO | G9: Gastos de Comida en Campamento PR | N9: -82.25 | P9: =SUM(Table134729[[#This Row],[Valor de la Factura del Cliente]:[Avance]]) -> -82.25
B10: 45703 | F10: COSTCO | G10: Gastos de Comida en Campamento PR | N10: -113.09 | P10: =SUM(Table134729[[#This Row],[Valor de la Factura del Cliente]:[Avance]])+P9 -> -195.34
B11: 45692 | F11: COSTCO | G11: Gastos de Comida en Campamento PR | N11: -62.66 | P11: =SUM(Table134729[[#This Row],[Valor de la Factura del Cliente]:[Avance]])+P10 -> -258
B12: 45704 | F12: COSTCO | G12: Gastos de Comida en Campamento PR | N12: -127.762 | P12: =SUM(Table134729[[#This Row],[Valor de la Factura del Cliente]:[Avance]])+P11 -> -385.762
B13: 45708 | F13: Spirit | G13: Vuelo San Juan - FLL | N13: -150.99 | P13: =SUM(Table134729[[#This Row],[Valor de la Factura del Cliente]:[Avance]])+P12 -> -536.752
G14: TOTAL | H14: =SUBTOTAL(109,Table134729[Valor de la Factura del Cliente]) -> 0 | I14: =SUBTOTAL(109,Table134729[Cargos Bancarios]) -> 0 | K14: =SUBTOTAL(109,Table134729[20% Comisión]) -> 0 | L14: =SUBTOTAL(109,Table134729[5% Legal]) -> 0 | M14: =SUBTOTAL(109,Table134729[Retención de Impuestos]) -> 0 | N14: =SUBTOTAL(109,Table134729[Pagado por MVPX]) -> -536.752 | O14: =SUBTOTAL(109,Table134729[Avance]) -> 0 | P14: =+#REF! -> #REF!

Sheet William Arteaga
B2: Artista:
B3: Nombre legal: | E3: William Arteaga
B4: Fecha de inicio: | E4: =MIN(Table134727[Fecha]) -> 45462
B5: Fecha fin: | E5: =MAX(Table134727[Fecha]) -> 45749
B7: ESTADO DE CUENTA
B8: Fecha | C8: Número | D8: Tipo | E8: Método de pago | F8: Nombre | G8: Concepto | H8: Valor de la Factura del Cliente | I8: Cargos Bancarios | J8: 50% Fee | K8: 20% Comisión | L8: 5% Legal | M8: Retención de Impuestos | N8: Pagado por MVPX | O8: Avance | P8: Balance
B9: 45462 | G9: Reseteo del Site Visa | O9: -20 | P9: =SUM(Table134727[[#This Row],[Valor de la Factura del Cliente]:[Avance]]) -> -20
B10: 45676 | F10: Taca Air | G10: Vuelo Colombia | O10: -143.4 | P10: =SUM(Table134727[[#This Row],[Valor de la Factura del Cliente]:[Avance]])+P9 -> -163.4
B11: 45690 | F11: Jet Blue | G11: Gastos de viaje | O11: -138.1 | P11: =SUM(Table134727[[#This Row],[Valor de la Factura del Cliente]:[Avance]])+P10 -> -301.5
B12: 45690 | F12: Jet Blue | G12: Gastos de viaje | O12: -232.41 | P12: =SUM(Table134727[[#This Row],[Valor de la Factura del Cliente]:[Avance]])+P11 -> -533.91
B13: 45690 | F13: Jet Blue | G13: Gastos de viaje | O13: -35 | P13: =SUM(Table134727[[#This Row],[Valor de la Factura del Cliente]:[Avance]])+P12 -> -568.91
B14: 45691 | F14: Costco | G14: Gastos de Comida Costco Camp PR | O14: -62.66 | P14: =SUM(Table134727[[#This Row],[Valor de la Factura del Cliente]:[Avance]])+P13 -> -631.57
B15: 45692 | F15: NewTasteChinese | G15: Gastos de Comida Costco Camp PR | O15: -31.02 | P15: =SUM(Table134727[[#This Row],[Valor de la Factura del Cliente]:[Avance]])+P14 -> -662.59
B16: 45697 | F16: Costco | G16: Gastos de Comida Costco Camp PR | O16: -82.25 | P16: =SUM(Table134727[[#This Row],[Valor de la Factura del Cliente]:[Avance]])+P15 -> -744.84
B17: 45703 | F17: Costco | G17: Gastos de Comida Costco Camp PR | O17: -113.09 | P17: =SUM(Table134727[[#This Row],[Valor de la Factura del Cliente]:[Avance]])+P16 -> -857.93
B18: 45749 | O18: -400 | P18: =SUM(Table134727[[#This Row],[Valor de la Factura del Cliente]:[Avance]])+P17 -> -1257.93
G19: TOTAL | H19: =SUBTOTAL(109,Table134727[Valor de la Factura del Cliente]) -> 0 | I19: =SUBTOTAL(109,Table134727[Cargos Bancarios]) -> 0 | K19: =SUBTOTAL(109,Table134727[20% Comisión]) -> 0 | L19: =SUBTOTAL(109,Table134727[5% Legal]) -> 0 | M19: =SUBTOTAL(109,Table134727[Retención de Impuestos]) -> 0 | N19: =SUBTOTAL(109,Table134727[Pagado por MVPX]) -> 0 | O19: =SUBTOTAL(109,Table134727[Avance]) -> -1257.93 | P19: =+#REF! -> #REF!

Sheet JayRozz
B2: Artista: | E2: JayRozz
B3: Nombre legal:
B4: Fecha de inicio: | E4: =MIN(Table134726[Fecha]) -> 45237
B5: Fecha fin: | E5: =MAX(Table134726[Fecha]) -> 45862
B7: ESTADO DE CUENTA
B8: Fecha | C8: Número | D8: Tipo | E8: Método de pago | F8: Nombre | G8: Concepto | H8: Valor de la Factura del Cliente | I8: Cargos Bancarios | J8: 50% Fee | K8: 20% Comisión | L8: 5% Legal | M8: Retención de Impuestos | N8: Pagado por MVPX | O8: Avance | P8: Balance
B9: 45856 | F9: Jaime Hospedales | G9: Adelantos a Jaime Hospedales | H9: 0 | I9: 0 | K9: 0 | L9: 0 | N9: 0 | O9: -536.752 | P9: =SUM(Table134726[[#This Row],[Cargos Bancarios]:[Avance]]) -> -536.752
B10: 45237 | F10: Nombre | G10: Adelanto Solicitado | H10: 0 | I10: 0 | K10: 0 | L10: 0 | N10: 0 | O10: -1000 | P10: =SUM(Table134726[[#This Row],[Cargos Bancarios]:[Avance]])+P9 -> -1536.752
B11: 45243 | F11: Jay Rozz | G11: Adelanto Solicitado | H11: 0 | I11: 0 | K11: 0 | L11: 0 | N11: 0 | O11: -4000 | P11: =SUM(Table134726[[#This Row],[Cargos Bancarios]:[Avance]])+P10 -> -5536.752
B12: 45287 | F12: Jay Rozz | G12: Adelanto Solicitado | H12: 0 | I12: 0 | K12: 0 | L12: 0 | N12: 0 | O12: -2000 | P12: =SUM(Table134726[[#This Row],[Cargos Bancarios]:[Avance]])+P11 -> -7536.752
B13: 45350 | F13: Jay Rozz | G13: Adelanto Solicitado | H13: 0 | I13: 0 | K13: 0 | L13: 0 | N13: 0 | O13: -11500 | P13: =SUM(Table134726[[#This Row],[Cargos Bancarios]:[Avance]])+P12 -> -19036.752
B14: 45369 | F14: Jay Rozz | G14: Adelanto Solicitado | H14: 0 | I14: 0 | K14: 0 | L14: 0 | N14: 0 | O14: -1000 | P14: =SUM(Table134726[[#This Row],[Cargos Bancarios]:[Avance]])+P13 -> -20036.752
B15: 45391 | F15: Jay Rozz | G15: Adelanto Solicitado | H15: 0 | I15: 0 | K15: 0 | L15: 0 | N15: 0 | O15: -300 | P15: =SUM(Table134726[[#This Row],[Cargos Bancarios]:[Avance]])+P14 -> -20336.752
B16: 45401 | F16: Jay Rozz | G16: Adelanto Solicitado | H16: 0 | I16: 0 | K16: 0 | L16: 0 | N16: 0 | O16: -200 | P16: =SUM(Table134726[[#This Row],[Cargos Bancarios]:[Avance]])+P15 -> -20536.752
B17: 45411 | F17: Jay Rozz | G17: Adelanto Solicitado | H17: 0 | I17: 0 | K17: 0 | L17: 0 | N17: 0 | O17: -500 | P17: =SUM(Table134726[[#This Row],[Cargos Bancarios]:[Avance]])+P16 -> -21036.752
B18: 45414 | F18: Pull&Bear | G18: Compra de Ropa | H18: 0 | I18: 0 | K18: 0 | L18: 0 | N18: 0 | O18: -115.48 | P18: =SUM(Table134726[[#This Row],[Cargos Bancarios]:[Avance]])+P17 -> -21152.232
B19: 45414 | F19: Rito y Monte MDE | G19: Comida en Colombia | H19: 0 | I19: 0 | K19: 0 | L19: 0 | N19: 0 | O19: -12.7 | P19: =SUM(Table134726[[#This Row],[Cargos Bancarios]:[Avance]])+P18 -> -21164.932
B20: 45414 | F20: Causa Poblado | G20: Comida en Colombia | H20: 0 | I20: 0 | K20: 0 | L20: 0 | N20: 0 | O20: -42.07 | P20: =SUM(Table134726[[#This Row],[Cargos Bancarios]:[Avance]])+P19 -> -21207.002
B21: 45424 | F21: AirBnB | G21: Pago de AirBnB Colombia | H21: 0 | I21: 0 | K21: 0 | L21: 0 | N21: 0 | O21: -216.565 | P21: =SUM(Table134726[[#This Row],[Cargos Bancarios]:[Avance]])+P20 -> -21423.567
... B45: 45509 | F45: Air Europa | G45: Pasaje de Regreso Madrid Venezuela | H45: 0 | I45: 0 | K45: 0 | L45: 0 | N45: 0 | O45: -432.55 | P45: =SUM(Table134726[[#This Row],[Cargos Bancarios]:[Avance]])+P44 -> -38776.399
B46: 45512 | F46: Jay Rozz | G46: Contrato Warner | H46: 200000 | I46: 0 | K46: -40000 | L46: -15000 | N46: 160000 | O46: 0 | P46: =SUM(Table134726[[#This Row],[Cargos Bancarios]:[Avance]])+P45-Table134726[[#This Row],[20% Comisión]] -> 106223.6
B47: 45515 | F47: Europa Air | G47: Madrid-Venezuela | H47: 0 | I47: 0 | K47: 0 | L47: 0 | N47: 0 | O47: -432.55 | P47: =SUM(Table134726[[#This Row],[Cargos Bancarios]:[Avance]])+P46 -> 105791.05
B48: 45516 | F48: Jay Rozz | G48: Adelanto Solicitado | H48: 0 | I48: 0 | K48: 0 | L48: 0 | N48: 0 | O48: -3500 | P48: =SUM(Table134726[[#This Row],[Cargos Bancarios]:[Avance]])+P47 -> 102291.05
B49: 45516 | F49: Jay Rozz | G49: Adelanto Solicitado | H49: 0 | I49: 0 | K49: 0 | L49: 0 | N49: 0 | O49: -1500 | P49: =SUM(Table134726[[#This Row],[Cargos Bancarios]:[Avance]])+P48 -> 100791.05
B50: 45522 | F50: Wingo | G50: Pasaje VEN-MED /MED-VEN (Cuñado Soccer) | H50: 0 | I50: 0 | K50: 0 | L50: 0 | N50: 0 | O50: -1544.54 | P50: =SUM(Table134726[[#This Row],[Cargos Bancarios]:[Avance]])+P49 -> 99246.511
B51: 45532 | F51: Jay Rozz | G51: Compra lo que quieras Corp | H51: 0 | I51: -25 | K51: 0 | L51: 0 | N51: 0 | O51: -3400 | P51: =SUM(Table134726[[#This Row],[Cargos Bancarios]:[Avance]])+P50 -> 95821.511
B52: 45532 | F52: Jay Rozz | G52: Compra lo que quieras Corp | H52: 0 | I52: -25 | K52: 0 | L52: 0 | N52: 0 | O52: -3500 | P52: =SUM(Table134726[[#This Row],[Cargos Bancarios]:[Avance]])+P51 -> 92296.511
B53: 45536 | F53: Airbnb | G53: Pago de Airbnb Medellin Colombia | H53: 0 | I53: 0 | K53: 0 | L53: 0 | N53: 0 | O53: -614 | P53: =SUM(Table134726[[#This Row],[Cargos Bancarios]:[Avance]])+P52 -> 91682.511
B54: 45536 | F54: Jay Rozz | G54: Adelanto Solicitado | H54: 0 | I54: 0 | K54: 0 | L54: 0 | N54: 0 | O54: -64600 | P54: =SUM(Table134726[[#This Row],[Cargos Bancarios]:[Avance]])+P53 -> 27082.511
B55: 45547 | F55: Jay Rozz | G55: Devolucion de Impuestos pagados en España | H55: 0 | I55: 0 | K55: 0 | L55: 0 | N55: 218.2 | O55: 0 | P55: =SUM(Table134726[[#This Row],[Cargos Bancarios]:[Avance]])+P54 -> 27300.711
B56: 45551 | F56: Jay Rozz | G56: Adelanto Solicitado | H56: 0 | I56: -25 | K56: 0 | L56: 0 | N56: 0 | O56: -3000 | P56: =SUM(Table134726[[#This Row],[Cargos Bancarios]:[Avance]])+P55 -> 24275.711
B57: 45554 | F57: Vueling Airlines | G57: Adelanto Solicitado | H57: 0 | I57: 0 | K57: 0 | L57: 0 | N57: 0 | O57: -2000 | P57: =SUM(Table134726[[#This Row],[Cargos Bancarios]:[Avance]])+P56 -> 22275.711
B58: 45568 | F58: Jay Rozz | G58: Adelanto Solicitado | H58: 0 | I58: 0 | K58: 0 | L58: 0 | N58: 0 | O58: -8497.46 | P58: =SUM(Table134726[[#This Row],[Cargos Bancarios]:[Avance]])+P57 -> 13778.251
... B61: 45666 | F61: Jay Rozz | G61: Adelanto Solicitado | H61: 0 | I61: 0 | K61: 0 | L61: 0 | N61: 0 | O61: -2500 | P61: =SUM(Table134726[[#This Row],[Cargos Bancarios]:[Avance]])+P60 -> 8433.2513
B62: 45674 | F62: Jay Rozz | G62: Contrato Warner Pago Pendiente 01/01/2025 | H62: 100000 | I62: 0 | K62: -20000 | L62: 0 | N62: 80000 | O62: 0 | P62: =SUM(Table134726[[#This Row],[Cargos Bancarios]:[Avance]])+P61-Table134726[[#This Row],[20% Comisión]] -> 88433.251
B63: 45675 | F63: Jay Rozz | G63: Hyatt BogotaConvention Center | H63: 0 | I63: 0 | K63: 0 | L63: 0 | N63: 0 | O63: -224.4 | P63: =SUM(Table134726[[#This Row],[Cargos Bancarios]:[Avance]])+P62 -> 88208.851
B64: 45676 | F64: Jay Rozz | G64: Pasaje Wingo de Caracas a Medellin | H64: 0 | I64: 0 | K64: 0 | L64: 0 | N64: 0 | O64: -176.3 | P64: =SUM(Table134726[[#This Row],[Cargos Bancarios]:[Avance]])+P63 -> 88032.551
B65: 45676 | F65: Taca Air | G65: Pasaje MDE BOG | H65: 0 | I65: 0 | K65: 0 | L65: 0 | N65: 0 | O65: -173.4 | P65: =SUM(Table134726[[#This Row],[Cargos Bancarios]:[Avance]])+P64 -> 87859.151
B66: 45677 | F66: Jay Rozz | G66: Pasaje de Avianca Medellin a Bogota (Pantera) | H66: 0 | I66: 0 | K66: 0 | L66: 0 | N66: 0 | O66: -143.4 | P66: =SUM(Table134726[[#This Row],[Cargos Bancarios]:[Avance]])+P65 -> 87715.751
B67: 45677 | F67: Jay Rozz | G67: Pasaje de Avianca Medellin a Bogota | H67: 0 | I67: 0 | K67: 0 | L67: 0 | N67: 0 | O67: -173.4 | P67: =SUM(Table134726[[#This Row],[Cargos Bancarios]:[Avance]])+P66 -> 87542.351
...

Sheet Marval
B2: Artista: | E2: Marval
B3: Nombre legal: | E3: Luis Marval
B4: Fecha de inicio: | E4: =MIN(Table134725[Fecha]) -> 45056
B5: Fecha fin: | E5: =MAX(Table134725[Fecha]) -> 45938
B7: ESTADO DE CUENTA
B8: Fecha | C8: Número | D8: Tipo | E8: Método de pago | F8: Nombre | G8: Concepto | H8: Valor de la Factura del Cliente | I8: Cargos Bancarios | J8: 50% Fee | K8: 20% Comisión | L8: 5% Legal | M8: Retención de Impuestos | N8: Pagado por MVPX | O8: Avance | P8: Balance
B9: x | F9: William Arteaga | G9: Gastos del Team Marval | N9: -1257.93 | P9: =SUM(Table134725[[#This Row],[Valor de la Factura del Cliente]:[Avance]]) -> -1257.93
B10: x | F10: Rene Da Silva | G10: Gastos del Team Marval | N10: -301.46167 | P10: =SUM(Table134725[[#This Row],[Valor de la Factura del Cliente]:[Avance]])+P9 -> -1559.3917
B11: x | F11: Cesar Dajoy | G11: Gastos del Team Marval | N11: -4788.3533 | P11: =SUM(Table134725[[#This Row],[Valor de la Factura del Cliente]:[Avance]])+P10 -> -6347.745
B12: 45056 | F12: Expedia | G12: Compra de Boleto para ir a Colombia | N12: -560 | P12: =SUM(Table134725[[#This Row],[Valor de la Factura del Cliente]:[Avance]])+P11 -> -6907.745
B13: 45097 | F13: Satena Bogota | G13: ADELANTO A RECUPERAR | N13: -391.01 | P13: =SUM(Table134725[[#This Row],[Valor de la Factura del Cliente]:[Avance]])+P12 -> -7298.755
B14: 45128 | F14: Luis Enrique Marval Paypal | G14: Adelanto a Recuperar | N14: -1000 | P14: =SUM(Table134725[[#This Row],[Valor de la Factura del Cliente]:[Avance]])+P13 -> -8298.755
B15: 45153 | F15: Luis Enrique Marval Paypal | G15: Adelanto a Recuperar | N15: -1000 | P15: =SUM(Table134725[[#This Row],[Valor de la Factura del Cliente]:[Avance]])+P14 -> -9298.755
B16: 45166 | F16: Godaddy luar lo pago | G16: Costo del dominio de MARVAL (macaiasongs.com) | N16: -66.22 | P16: =SUM(Table134725[[#This Row],[Valor de la Factura del Cliente]:[Avance]])+P15 -> -9364.975
B17: 45165 | F17: Coorporate Filing LLC | G17: Coorporate Filing | N17: -244 | P17: =SUM(Table134725[[#This Row],[Valor de la Factura del Cliente]:[Avance]])+P16 -> -9608.975
B18: 45175 | F18: Coorporate Filing LLC | G18: Amendment filing | N18: -125 | P18: =SUM(Table134725[[#This Row],[Valor de la Factura del Cliente]:[Avance]])+P17 -> -9733.975
B19: 45183 | F19: PAYPAL | G19: ADELANTO A RECUPERAR | N19: -2000 | P19: =SUM(Table134725[[#This Row],[Valor de la Factura del Cliente]:[Avance]])+P18 -> -11733.975
B20: 45184 | F20: PAYPAL | G20: Adelanto del contrato de Productor a Jeidi | N20: -7000 | P20: =SUM(Table134725[[#This Row],[Valor de la Factura del Cliente]:[Avance]])+P19 -> -18733.975
B21: 45211 | F21: Marval | G21: Marval Advanced | N21: -1000 | P21: =SUM(Table134725[[#This Row],[Valor de la Factura del Cliente]:[Avance]])+P20 -> -19733.975
B22: 45218 | F22: Microsoft- Discover | G22: Email Plus Expense (MicaiaSongs) | N22: -21.43 | P22: =SUM(Table134725[[#This Row],[Valor de la Factura del Cliente]:[Avance]])+P21 -> -19755.405
B23: 45219 | F23: Mr Marval | G23: Adelanto al Padre de Marval | N23: -9000 | P23: =SUM(Table134725[[#This Row],[Valor de la Factura del Cliente]:[Avance]])+P22 -> -28755.405
B24: 45226 | F24: Coorporate Filing LLC | G24: Coorporate Filing | N24: -9 | P24: =SUM(Table134725[[#This Row],[Valor de la Factura del Cliente]:[Avance]])+P23 -> -28764.405
B25: 45238 | G25: Advanced Payment | N25: -8100 | P25: =SUM(Table134725[[#This Row],[Valor de la Factura del Cliente]:[Avance]])+P24 -> -36864.405
B26: 45244 | F26: Luigi SCALETTA | G26: Avance Marval Compra de Computadora | N26: -1315 | P26: =SUM(Table134725[[#This Row],[Valor de la Factura del Cliente]:[Avance]])+P25 -> -38179.405
B27: 45265 | G27: Pasaje de MDE (Colombia) - CCS (Venezuela) | N27: -615 | P27: =SUM(Table134725[[#This Row],[Valor de la Factura del Cliente]:[Avance]])+P26 -> -38794.405
B28: 45266 | G28: Total Recibido a la fecha | H28: 125000 | N28: 0 | P28: =SUM(Table134725[[#This Row],[Valor de la Factura del Cliente]:[Avance]])+P27 -> 86205.595
G29: Pagado a Matt Greenberg (Legal Services Contrato Pub) | N29: -17500 | P29: =SUM(Table134725[[#This Row],[Valor de la Factura del Cliente]:[Avance]])+P28 -> 68705.595
G30: Pago del asesoramiento 10% | N30: -36000 | P30: =SUM(Table134725[[#This Row],[Valor de la Factura del Cliente]:[Avance]])+P29 -> 32705.595
G31: Dimelo Super | N31: -36000 | P31: =SUM(Table134725[[#This Row],[Valor de la Factura del Cliente]:[Avance]])+P30 -> -3294.405
B32: 45267 | G32: Avance | N32: -3053.34 | P32: =SUM(Table134725[[#This Row],[Valor de la Factura del Cliente]:[Avance]])+P31 -> -6347.745
B33: 45299 | F33: Zelle | G33: Advanced Payment | N33: -3000 | P33: =SUM(Table134725[[#This Row],[Valor de la Factura del Cliente]:[Avance]])+P32 -> -9347.745
B34: 45329 | F34: Zelle | G34: Avance | N34: -1000 | P34: =SUM(Table134725[[#This Row],[Valor de la Factura del Cliente]:[Avance]])+P33 -> -10347.745
B35: 45344 | F35: Zelle | G35: Avance | N35: -1000 | P35: =SUM(Table134725[[#This Row],[Valor de la Factura del Cliente]:[Avance]])+P34 -> -11347.745
B36: 45360 | F36: Zelle | G36: Pago por la empresa de MICAIA SONGS | N36: -238.75 | P36: =SUM(Table134725[[#This Row],[Valor de la Factura del Cliente]:[Avance]])+P35 -> -11586.495
B37: 45369 | F37: Zelle | G37: Adelanto de Video | N37: -750 | P37: =SUM(Table134725[[#This Row],[Valor de la Factura del Cliente]:[Avance]])+P36 -> -12336.495
B38: 45379 | F38: Zelle | G38: Adelanto de Video | N38: -1500 | P38: =SUM(Table134725[[#This Row],[Valor de la Factura del Cliente]:[Avance]])+P37 -> -13836.495
B39: 45398 | F39: Zelle | G39: Advanced Payment | N39: -1000 | P39: =SUM(Table134725[[#This Row],[Valor de la Factura del Cliente]:[Avance]])+P38 -> -14836.495
B40: 45414 | F40: Capital One | G40: Comida en Colombia | N40: -42.05 | P40: =SUM(Table134725[[#This Row],[Valor de la Factura del Cliente]:[Avance]])+P39 -> -14878.545
B41: 45423 | F41: Capital One | G41: AirBnB en Colombia | N41: -216.565 | P41: =SUM(Table134725[[#This Row],[Valor de la Factura del Cliente]:[Avance]])+P40 -> -15095.11
B42: 45434 | F42: Capital One | G42: Pago de AirBnB en Colombia | N42: -287.11 | P42: =SUM(Table134725[[#This Row],[Valor de la Factura del Cliente]:[Avance]])+P41 -> -15382.22
...

Sheet Dimelo Super
B2: Artista: | E2: Dimelo Super
B3: Nombre legal: | E3: Jesus Perea
B4: Fecha de inicio: | E4: =MIN(Table134724[Fecha]) -> 45109
B5: Fecha fin: | E5: =MAX(Table134724[Fecha]) -> 45665
B7: ESTADO DE CUENTA
B8: Fecha | C8: Número | D8: Tipo | E8: Método de pago | F8: Nombre | G8: Concepto | H8: Valor de la Factura del Cliente | I8: Cargos Bancarios | J8: 50% Fee | K8: 20% Comisión | L8: 5% Legal | M8: Retención de Impuestos | N8: Pagado por MVPX | O8: Avance | P8: Balance
G9: Ingreso del 10% del contrato de Marval | H9: 36500 | P9: =SUM(Table134724[[#This Row],[Valor de la Factura del Cliente]:[Avance]]) -> 36500
G10: Ingreso del 10% del contrato de JROZZ | H10: 30000 | P10: =SUM(Table134724[[#This Row],[Valor de la Factura del Cliente]:[Avance]])+P9 -> 66500
G11: Ingreso del 10% del contrato de JROZZ bmi | H11: 12500 | P11: =SUM(Table134724[[#This Row],[Valor de la Factura del Cliente]:[Avance]])+P10 -> 79000
G12: Pagado por Servicios de ECBY | N12: -1000 | P12: =SUM(Table134724[[#This Row],[Valor de la Factura del Cliente]:[Avance]])+P11 -> 78000
B13: 45109 | F13: Dimelo Super | G13: Avance Solicitado | I13: -7.99 | N13: -800 | P13: =SUM(Table134724[[#This Row],[Valor de la Factura del Cliente]:[Avance]])+P12 -> 77192.01
B14: 45139 | F14: Dimelo Super | G14: Avance Solicitado | I14: -7.99 | N14: -800 | P14: =SUM(Table134724[[#This Row],[Valor de la Factura del Cliente]:[Avance]])+P13 -> 76384.02
B15: 45175 | F15: Dimelo Super | G15: Avance Solicitado | I15: -7.99 | N15: -800 | P15: =SUM(Table134724[[#This Row],[Valor de la Factura del Cliente]:[Avance]])+P14 -> 75576.03
B16: 45191 | F16: Dimelo Super | G16: Avance Solicitado | I16: -7.99 | N16: -800 | P16: =SUM(Table134724[[#This Row],[Valor de la Factura del Cliente]:[Avance]])+P15 -> 74768.04
B17: 45233 | F17: Dimelo Super | G17: Avance Solicitado | I17: -7.99 | N17: -800 | P17: =SUM(Table134724[[#This Row],[Valor de la Factura del Cliente]:[Avance]])+P16 -> 73960.05
B18: 45233 | F18: Dimelo Super | G18: Avance Solicitado | I18: -25 | N18: -5000 | P18: =SUM(Table134724[[#This Row],[Valor de la Factura del Cliente]:[Avance]])+P17 -> 68935.05
B19: 45278 | F19: Dimelo Super | G19: Avance Solicitado | I19: -7.99 | N19: -1000 | P19: =SUM(Table134724[[#This Row],[Valor de la Factura del Cliente]:[Avance]])+P18 -> 67927.06
B20: 45279 | F20: Dimelo Super | G20: Avance Solicitado | I20: -25 | N20: -5000 | P20: =SUM(Table134724[[#This Row],[Valor de la Factura del Cliente]:[Avance]])+P19 -> 62902.06
B21: 45414 | F21: Causa Poblado | G21: Meal Covered | N21: -42.05 | P21: =SUM(Table134724[[#This Row],[Valor de la Factura del Cliente]:[Avance]])+P20 -> 62860.01
B22: 45464 | F22: Natalia Romero | G22: Pasajes Cubiertos, Juan Arias y Jerus Perea 1380 Natalia Romero | N22: -690 | P22: =SUM(Table134724[[#This Row],[Valor de la Factura del Cliente]:[Avance]])+P21 -> 62170.01
B23: 45486 | F23: EuropaAir | G23: Europa Air - Gastos Víaticos | N23: -224.1 | P23: =SUM(Table134724[[#This Row],[Valor de la Factura del Cliente]:[Avance]])+P22 -> 61945.91
B24: 45494 | F24: El Moli Menjars Valencians | G24: Se divide entre 5, marval, rozz, super y 2 de lopez | N24: -52.046 | P24: =SUM(Table134724[[#This Row],[Valor de la Factura del Cliente]:[Avance]])+P23 -> 61893.864
B25: 45502 | F25: El Rincon de Maria | G25: Comida en España entre Marval, Rozz, Lopez y Super | N25: -61.6725 | P25: =SUM(Table134724[[#This Row],[Valor de la Factura del Cliente]:[Avance]])+P24 -> 61832.191
B26: 45506 | F26: Aroma de Mar | G26: Comida en España entre Marval, Rozz, Lopez y Super | N26: -65.5125 | P26: =SUM(Table134724[[#This Row],[Valor de la Factura del Cliente]:[Avance]])+P25 -> 61766.679
B27: 45509 | F27: Avianca | G27: Pasaje Madrid-Colombia | N27: -836.8 | P27: =SUM(Table134724[[#This Row],[Valor de la Factura del Cliente]:[Avance]])+P26 -> 60929.879
B28: 45629 | F28: bofa | G28: Transferido vía bofa | N28: -600 | P28: =SUM(Table134724[[#This Row],[Valor de la Factura del Cliente]:[Avance]])+P27 -> 60329.879
B29: 45646 | F29: wingo | G29: cita de la visa que viajaron a Bogota | N29: -274.47 | P29: =SUM(Table134724[[#This Row],[Valor de la Factura del Cliente]:[Avance]])+P28 -> 60055.409
B30: 45658 | F30: remitly | G30: Pagado a Ingrid Katherin Virviescas Valbuena por la Visa | N30: -345 | P30: =SUM(Table134724[[#This Row],[Valor de la Factura del Cliente]:[Avance]])+P29 -> 59710.409
B31: 45660 | F31: TACA AIR | G31: MDE - BOG Gastos de Viaje | N31: -132.4 | P31: =SUM(Table134724[[#This Row],[Valor de la Factura del Cliente]:[Avance]])+P30 -> 59578.009
B32: 45660 | F32: EXPIDIA | G32: ESTADIA EN BOGOTA GASTOS COMPARTIDO CON MARVAL | N32: -135 | P32: =SUM(Table134724[[#This Row],[Valor de la Factura del Cliente]:[Avance]])+P31 -> 59443.009
B33: 45665 | F33: TACA AIR | G33: BOG - MDE | N33: -97.8 | P33: =SUM(Table134724[[#This Row],[Valor de la Factura del Cliente]:[Avance]])+P32 -> 59345.209
G34: TOTAL | H34: =SUBTOTAL(109,Table134724[Valor de la Factura del Cliente]) -> 79000 | I34: =SUBTOTAL(109,Table134724[Cargos Bancarios]) -> -97.94 | K34: =SUBTOTAL(109,Table134724[20% Comisión]) -> 0 | L34: =SUBTOTAL(109,Table134724[5% Legal]) -> 0 | M34: =SUBTOTAL(109,Table134724[Retención de Impuestos]) -> 0 | N34: =SUBTOTAL(109,Table134724[Pagado por MVPX]) -> -19556.851 | O34: =SUBTOTAL(109,Table134724[Avance]) -> 0 | P34: =+P33 -> 59345.209

Sheet Samuel Velazquez
B2: Artista: | E2: Samuel Velazquez
B3: Nombre legal: | E3: =+E2 -> Samuel Velazquez
B4: Fecha de inicio: | E4: =MIN(Table134710[Fecha]) -> 45219
B5: Fecha fin: | E5: =MAX(Table134710[Fecha]) -> 45555
B7: ESTADO DE CUENTA
B8: Fecha | C8: Número | D8: Tipo | E8: Método de pago | F8: Nombre | G8: Concepto | H8: Valor de la Factura del Cliente | I8: Cargos Bancarios | J8: 50% Fee | K8: 20% Comisión | L8: 5% Legal | M8: Retención de Impuestos | N8: Pagado por MVPX | O8: Avance | P8: Balance
B9: 45404 | F9: Samuel Velazquez | G9: Arreglo y produccion, post producción y Guitarras | H9: 3600 | P9: =SUM(Table134710[[#This Row],[Valor de la Factura del Cliente]:[Avance]]) -> 3600
B10: 45219 | F10: Samuel Velazquez | G10: Adelanto Solicitado | N10: -654.45 | P10: =SUM(Table134710[[#This Row],[Valor de la Factura del Cliente]:[Avance]])+P9 -> 2945.55
B11: 45413 | F11: Samuel Velazquez | G11: Adelanto Solicitado | N11: -804.99 | P11: =SUM(Table134710[[#This Row],[Valor de la Factura del Cliente]:[Avance]])+P10 -> 2140.56
B12: 45465 | F12: Samuel Velazquez | G12: Adelanto Solicitado | N12: -597 | P12: =SUM(Table134710[[#This Row],[Valor de la Factura del Cliente]:[Avance]])+P11 -> 1543.56
B13: 45553 | F13: Samuel Velazquez | G13: Adelanto Solicitado | N13: -550 | P13: =SUM(Table134710[[#This Row],[Valor de la Factura del Cliente]:[Avance]])+P12 -> 993.56
B14: 45554 | F14: 3 Val Tech | G14: Pago vía Bofa | N14: -160 | P14: =SUM(Table134710[[#This Row],[Valor de la Factura del Cliente]:[Avance]])+P13 -> 833.56
B15: 45555 | F15: Samuel Velazquez | G15: Adelanto Solicitado | N15: -832.5 | P15: =SUM(Table134710[[#This Row],[Valor de la Factura del Cliente]:[Avance]])+P14 -> 1.06
B16: 45332 | F16: Samuel Velazquez | G16: Adelanto Solicitado | N16: -841.99 | P16: =SUM(Table134710[[#This Row],[Valor de la Factura del Cliente]:[Avance]])+P15 -> -840.93
G17: TOTAL | H17: =SUBTOTAL(109,Table134710[Valor de la Factura del Cliente]) -> 3600 | I17: =SUBTOTAL(109,Table134710[Cargos Bancarios]) -> 0 | K17: =SUBTOTAL(109,Table134710[20% Comisión]) -> 0 | L17: =SUBTOTAL(109,Table134710[5% Legal]) -> 0 | M17: =SUBTOTAL(109,Table134710[Retención de Impuestos]) -> 0 | N17: =SUBTOTAL(109,Table134710[Pagado por MVPX]) -> -4440.93 | O17: =SUBTOTAL(109,Table134710[Avance]) -> 0 | P17: =+P16 -> -840.93

Sheet Alex Nuñez
B2: Artista: | E2: Alex Nuñez
B3: Nombre legal: | E3: Alex Nuñez
B4: Fecha de inicio: | E4: =MIN(Table13473[Fecha]) -> 45166
B5: Fecha fin: | E5: =MAX(Table13473[Fecha]) -> 45945
B7: ESTADO DE CUENTA
B8: Fecha | C8: Número | D8: Tipo | E8: Método de pago | F8: Nombre | G8: Concepto | H8: Valor de la Factura del Cliente | I8: Cargos Bancarios | J8: 50% Fee | K8: 20% Comisión | L8: 5% Legal | M8: Retención de Impuestos | N8: Pagado por MVPX | O8: Avance | P8: Balance
B9: 45166 | F9: Sra Sara Pimentel | G9: Adelanto Solicitado | N9: -20000 | P9: =SUM(Table13473[[#This Row],[Valor de la Factura del Cliente]:[Avance]]) -> -20000
B10: 45166 | F10: Sra Nancy Guzman | G10: Adelanto Solicitado | N10: -70000 | P10: =SUM(Table13473[[#This Row],[Valor de la Factura del Cliente]:[Avance]])+P9 -> -90000
B11: 45191 | F11: Alex Nuñez | G11: Adelanto Solicitado | N11: -5000 | P11: =SUM(Table13473[[#This Row],[Valor de la Factura del Cliente]:[Avance]])+P10 -> -95000
B12: 45199 | F12: Uber | G12: Transporte a la Filmacion | N12: -300 | P12: =SUM(Table13473[[#This Row],[Valor de la Factura del Cliente]:[Avance]])+P11 -> -95300
B13: 45200 | F13: SuperM Nacional | G13: Comida para la Filmación | N13: -12000 | P13: =SUM(Table13473[[#This Row],[Valor de la Factura del Cliente]:[Avance]])+P12 -> -107300
B14: 45375 | F14: Alex Nuñez | G14: Adelanto para la visa | N14: -28800 | P14: =SUM(Table13473[[#This Row],[Valor de la Factura del Cliente]:[Avance]])+P13 -> -136100
B15: 45386 | F15: Uber | G15: Transporte para el campamento | N15: -364.58 | P15: =SUM(Table13473[[#This Row],[Valor de la Factura del Cliente]:[Avance]])+P14 -> -136464.58
B16: 45387 | F16: SuperM Nacional | G16: Comida para campamento | N16: -8982.19 | P16: =SUM(Table13473[[#This Row],[Valor de la Factura del Cliente]:[Avance]])+P15 -> -145446.77
B17: 45387 | F17: Transporte al campamento | G17: Transporte para el campamento | N17: -2500 | P17: =SUM(Table13473[[#This Row],[Valor de la Factura del Cliente]:[Avance]])+P16 -> -147946.77
B18: 45396 | F18: Sara Esther Pimentel Nuñez | G18: Adelanto realizado vía remitly | N18: -9239 | P18: =SUM(Table13473[[#This Row],[Valor de la Factura del Cliente]:[Avance]])+P17 -> -157185.77
B19: 45400 | F19: Alex Nuñez | G19: Comida para el 2do Campamento | N19: -4075 | P19: =SUM(Table13473[[#This Row],[Valor de la Factura del Cliente]:[Avance]])+P18 -> -161260.77
B20: 45401 | F20: Uber | G20: Gastos de Transporte para el Campamento | N20: -421.92 | P20: =SUM(Table13473[[#This Row],[Valor de la Factura del Cliente]:[Avance]])+P19 -> -161682.69
B21: 45402 | F21: XIOMERI VELOZ | G21: Pago de Comida para el Campamento (Lo pago gesa) | N21: -7000 | P21: =SUM(Table13473[[#This Row],[Valor de la Factura del Cliente]:[Avance]])+P20 -> -168682.69
... B91: 45877 | F91: Pago de la renta | G91: Sara pago 7 y gesa 15 | N91: -15000 | P91: =SUM(Table13473[[#This Row],[Valor de la Factura del Cliente]:[Avance]])+P90 -> -1598525.1
B92: 45874 | F92: Ingreso | G92: Pgo del seguro por el carro | H92: 805103.56 | N92: 0 | P92: =SUM(Table13473[[#This Row],[Valor de la Factura del Cliente]:[Avance]])+P91 -> -793421.54
B93: 45883 | F93: Price Smart | G93: Compra de Comida para la casa de Alex | N93: -2349.5 | P93: =SUM(Table13473[[#This Row],[Valor de la Factura del Cliente]:[Avance]])+P92 -> -795771.04
B94: 45883 | F94: Bravo | G94: Compra de Comida para la casa de Alex | N94: -6890 | P94: =SUM(Table13473[[#This Row],[Valor de la Factura del Cliente]:[Avance]])+P93 -> -802661.04
B95: 45901 | F95: Colegio Niños | G95: Pago a Nancy Guzman por el 80% del monto adeudado | N95: -90400 | P95: =SUM(Table13473[[#This Row],[Valor de la Factura del Cliente]:[Avance]])+P94 -> -893061.04
B96: 45902 | F96: Max Ferretería | G96: Compra de Cuadernos para el colegio (40) | N96: -960 | P96: =SUM(Table13473[[#This Row],[Valor de la Factura del Cliente]:[Avance]])+P95 -> -894021.04
B97: 45902 | F97: Sirena | G97: Papel Cuadriculado y Resma de Papel | N97: -524 | P97: =SUM(Table13473[[#This Row],[Valor de la Factura del Cliente]:[Avance]])+P96 -> -894545.04
B98: 45902 | F98: Pago de la renta | G98: Sara pago 08 y gesa 14 | N98: -14000 | P98: =SUM(Table13473[[#This Row],[Valor de la Factura del Cliente]:[Avance]])+P97 -> -908545.04
B99: 45904 | F99: SR Julio y Surinach Perez | G99: Compra de Libros del colegio para los hijos de alex | N99: -8800 | P99: =SUM(Table13473[[#This Row],[Valor de la Factura del Cliente]:[Avance]])+P98 -> -917345.04
B100: 45906 | F100: Bravo | G100: Compra de Comida para la casa de Alex | N100: -7806 | P100: =SUM(Table13473[[#This Row],[Valor de la Factura del Cliente]:[Avance]])+P99 -> -925151.04
B101: 45912 | F101: Uber | G101: Gasto de Uber del colegio | N101: -195 | P101: =SUM(Table13473[[#This Row],[Valor de la Factura del Cliente]:[Avance]])+P100 -> -925346.04
B102: 45912 | F102: Price Smart | G102: Compra de Comida para la casa de Alex | N102: -540 | P102: =SUM(Table13473[[#This Row],[Valor de la Factura del Cliente]:[Avance]])+P101 -> -925886.04
B103: 45912 | F103: Price Smart | G103: Compra de Comida para la casa de Alex | N103: -1903.9 | P103: =SUM(Table13473[[#This Row],[Valor de la Factura del Cliente]:[Avance]])+P102 -> -927789.94
B104: 45913 | F104: Teomedes Cesar Isabel Placencio | G104: Pago a Musicos de Alex (1000 usd) | N104: -61580 | P104: =SUM(Table13473[[#This Row],[Valor de la Factura del Cliente]:[Avance]])+P103 -> -989369.94
... B110: 45945 | F110: Edesur | G110: Pago de la Luz | N110: -3744.39 | P110: =SUM(Table13473[[#This Row],[Valor de la Factura del Cliente]:[Avance]])+P109 -> -1106480.6
N111: 0 | P111: =SUM(Table13473[[#This Row],[Valor de la Factura del Cliente]:[Avance]])+P110 -> -1106480.6
N112: 0 | P112: =SUM(Table13473[[#This Row],[Valor de la Factura del Cliente]:[Avance]])+P111 -> -1106480.6
N113: 0 | P113: =SUM(Table13473[[#This Row],[Valor de la Factura del Cliente]:[Avance]])+P112 -> -1106480.6
N114: 0 | P114: =SUM(Table13473[[#This Row],[Valor de la Factura del Cliente]:[Avance]])+P113 -> -1106480.6
N115: 0 | P115: =SUM(Table13473[[#This Row],[Valor de la Factura del Cliente]:[Avance]])+P114 -> -1106480.6
N116: 0 | P116: =SUM(Table13473[[#This Row],[Valor de la Factura del Cliente]:[Avance]])+P115 -> -1106480.6
...

Sheet Divino
B2: Artista: | E2: Divino
B3: Nombre legal: | E3: Daniel Velazquez
B4: Fecha de inicio: | E4: =MIN(Table134723[Fecha]) -> 44692
B5: Fecha fin: | E5: =MAX(Table134723[Fecha]) -> 45930
B7: ESTADO DE CUENTA
B8: Fecha | C8: Número | D8: Tipo | E8: Método de pago | F8: Nombre | G8: Concepto | H8: Valor de la Factura del Cliente | I8: Cargos Bancarios | J8: 50% Fee | K8: 10% Comisión | L8: 5% Legal | M8: Retención de Impuestos | N8: Pagado por MVPX | O8: Avance | P8: Balance
B9: Enero 2023 | G9: Reporte ingresos por la Distribución de Todo a su Tiempo | H9: 0 | J9: =-Table134723[[#This Row],[Valor de la Factura del Cliente]]*0.5 -> 0 | P9: =SUM(Table134723[[#This Row],[Valor de la Factura del Cliente]:[Avance]]) -> 0
B10: Febrero 2023 | G10: Reporte ingresos por la Distribución de Todo a su Tiempo | H10: 112.88501 | J10: =-Table134723[[#This Row],[Valor de la Factura del Cliente]]*0.5 -> -56.442505 | P10: =SUM(Table134723[[#This Row],[Valor de la Factura del Cliente]:[Avance]])+P9 -> 56.442505
B11: Marzo 2023 | G11: Reporte ingresos por la Distribución de Todo a su Tiempo | H11: 168.6371 | J11: =-Table134723[[#This Row],[Valor de la Factura del Cliente]]*0.5 -> -84.318548 | P11: =SUM(Table134723[[#This Row],[Valor de la Factura del Cliente]:[Avance]])+P10 -> 140.76105
B12: Abril 2023 | G12: Reporte ingresos por la Distribución de Todo a su Tiempo | H12: 243.98148 | J12: =-Table134723[[#This Row],[Valor de la Factura del Cliente]]*0.5 -> -121.99074 | P12: =SUM(Table134723[[#This Row],[Valor de la Factura del Cliente]:[Avance]])+P11 -> 262.75179
B13: Mayo 2023 | G13: Reporte ingresos por la Distribución de Todo a su Tiempo | H13: 257.37564 | J13: =-Table134723[[#This Row],[Valor de la Factura del Cliente]]*0.5 -> -128.68782 | P13: =SUM(Table134723[[#This Row],[Valor de la Factura del Cliente]:[Avance]])+P12 -> 391.43961
B14: Junio 2023 | G14: Reporte ingresos por la Distribución de Todo a su Tiempo | H14: 335.23941 | J14: =-Table134723[[#This Row],[Valor de la Factura del Cliente]]*0.5 -> -167.6197 | P14: =SUM(Table134723[[#This Row],[Valor de la Factura del Cliente]:[Avance]])+P13 -> 559.05931
B15: Julio 2023 | G15: Reporte ingresos por la Distribución de Todo a su Tiempo | H15: 620.16151 | J15: =-Table134723[[#This Row],[Valor de la Factura del Cliente]]*0.5 -> -310.08075 | P15: =SUM(Table134723[[#This Row],[Valor de la Factura del Cliente]:[Avance]])+P14 -> 869.14007
B16: Agosto 2023 | G16: Reporte ingresos por la Distribución de Todo a su Tiempo | H16: 818.55702 | J16: =-Table134723[[#This Row],[Valor de la Factura del Cliente]]*0.5 -> -409.27851 | P16: =SUM(Table134723[[#This Row],[Valor de la Factura del Cliente]:[Avance]])+P15 -> 1278.4186
B17: Septiembre 2023 | G17: Reporte ingresos por la Distribución de Todo a su Tiempo | H17: 736.00881 | J17: =-Table134723[[#This Row],[Valor de la Factura del Cliente]]*0.5 -> -368.0044 | P17: =SUM(Table134723[[#This Row],[Valor de la Factura del Cliente]:[Avance]])+P16 -> 1646.423
B18: Octubre 2023 | G18: Reporte ingresos por la Distribución de Todo a su Tiempo | H18: 820.51103 | J18: =-Table134723[[#This Row],[Valor de la Factura del Cliente]]*0.5 -> -410.25552 | P18: =SUM(Table134723[[#This Row],[Valor de la Factura del Cliente]:[Avance]])+P17 -> 2056.6785
B19: Noviembre 2023 | G19: Reporte ingresos por la Distribución de Todo a su Tiempo | H19: 701.38358 | J19: =-Table134723[[#This Row],[Valor de la Factura del Cliente]]*0.5 -> -350.69179 | P19: =SUM(Table134723[[#This Row],[Valor de la Factura del Cliente]:[Avance]])+P18 -> 2407.3703
B20: Diciembre 2023 | G20: Reporte ingresos por la Distribución de Todo a su Tiempo | H20: 697.46252 | J20: =-Table134723[[#This Row],[Valor de la Factura del Cliente]]*0.5 -> -348.73126 | P20: =SUM(Table134723[[#This Row],[Valor de la Factura del Cliente]:[Avance]])+P19 -> 2756.1015
B21: Enero 2024 | G21: Reporte ingresos por la Distribución de Todo a su Tiempo | H21: 706.0576 | J21: =-Table134723[[#This Row],[Valor de la Factura del Cliente]]*0.5 -> -353.0288 | P21: =SUM(Table134723[[#This Row],[Valor de la Factura del Cliente]:[Avance]])+P20 -> 3109.1303
... B39: Julio 2025 | G39: Reporte ingresos por la Distribución de Todo a su Tiempo | H39: 3848.3893 | J39: =-Table134723[[#This Row],[Valor de la Factura del Cliente]]*0.5 -> -1924.1947 | P39: =SUM(Table134723[[#This Row],[Valor de la Factura del Cliente]:[Avance]])+P38 -> 14688.353
B40: Q32020 | G40: Reporte de Regalías Mecanicas | H40: 0 | K40: =-Table134723[[#This Row],[Valor de la Factura del Cliente]]*0.1 -> 0 | P40: =SUM(Table134723[[#This Row],[Valor de la Factura del Cliente]:[Avance]])+P39 -> 14688.353
B41: Q42020 | G41: Reporte de Regalías Mecanicas | H41: 385.77 | K41: =-Table134723[[#This Row],[Valor de la Factura del Cliente]]*0.1 -> -38.577 | P41: =SUM(Table134723[[#This Row],[Valor de la Factura del Cliente]:[Avance]])+P40 -> 15035.546
B42: Q12021 | G42: Reporte de Regalías Mecanicas | H42: 482.31 | K42: =-Table134723[[#This Row],[Valor de la Factura del Cliente]]*0.1 -> -48.231 | P42: =SUM(Table134723[[#This Row],[Valor de la Factura del Cliente]:[Avance]])+P41 -> 15469.625
B43: Q22021 | G43: Reporte de Regalías Mecanicas | H43: 237.31 | K43: =-Table134723[[#This Row],[Valor de la Factura del Cliente]]*0.1 -> -23.731 | P43: =SUM(Table134723[[#This Row],[Valor de la Factura del Cliente]:[Avance]])+P42 -> 15683.204
B44: Q32021 | G44: Reporte de Regalías Mecanicas | H44: 2649.44 | K44: =-Table134723[[#This Row],[Valor de la Factura del Cliente]]*0.1 -> -264.944 | P44: =SUM(Table134723[[#This Row],[Valor de la Factura del Cliente]:[Avance]])+P43 -> 18067.7
B45: Q42021 | G45: Reporte de Regalías Mecanicas | H45: 2165.34 | K45: =-Table134723[[#This Row],[Valor de la Factura del Cliente]]*0.1 -> -216.534 | P45: =SUM(Table134723[[#This Row],[Valor de la Factura del Cliente]:[Avance]])+P44 -> 20016.506
B46: Q12022 | G46: Reporte de Regalías Mecanicas | H46: 174.56 | K46: =-Table134723[[#This Row],[Valor de la Factura del Cliente]]*0.1 -> -17.456 | P46: =SUM(Table134723[[#This Row],[Valor de la Factura del Cliente]:[Avance]])+P45 -> 20173.61
B47: Q22022 | G47: Reporte de Regalías Mecanicas | H47: 333.31 | K47: =-Table134723[[#This Row],[Valor de la Factura del Cliente]]*0.1 -> -33.331 | P47: =SUM(Table134723[[#This Row],[Valor de la Factura del Cliente]:[Avance]])+P46 -> 20473.589
B48: Q32022 | G48: Reporte de Regalías Mecanicas | H48: 319.33 | K48: =-Table134723[[#This Row],[Valor de la Factura del Cliente]]*0.1 -> -31.933 | P48: =SUM(Table134723[[#This Row],[Valor de la Factura del Cliente]:[Avance]])+P47 -> 20760.986
B49: Q42022 | G49: Reporte de Regalías Mecanicas | H49: 306.61 | K49: =-Table134723[[#This Row],[Valor de la Factura del Cliente]]*0.1 -> -30.661 | P49: =SUM(Table134723[[#This Row],[Valor de la Factura del Cliente]:[Avance]])+P48 -> 21036.935
B50: Q12023 | G50: Reporte de Regalías Mecanicas | H50: 858.01 | K50: =-Table134723[[#This Row],[Valor de la Factura del Cliente]]*0.1 -> -85.801 | P50: =SUM(Table134723[[#This Row],[Valor de la Factura del Cliente]:[Avance]])+P49 -> 21809.144
B51: Q22023 | G51: Reporte de Regalías Mecanicas | H51: 1061.76 | K51: =-Table134723[[#This Row],[Valor de la Factura del Cliente]]*0.1 -> -106.176 | P51: =SUM(Table134723[[#This Row],[Valor de la Factura del Cliente]:[Avance]])+P50 -> 22764.728
... B59: Q22025 | G59: Reporte de Regalías Mecanicas | H59: 9070.07 | K59: =-Table134723[[#This Row],[Valor de la Factura del Cliente]]*0.1 -> -907.007 | P59: =SUM(Table134723[[#This Row],[Valor de la Factura del Cliente]:[Avance]])+P58 -> 64033.544
B60: 44692 | G60: Pagos Realizados | N60: -5583.7 | P60: =SUM(Table134723[[#This Row],[Valor de la Factura del Cliente]:[Avance]])+P59 -> 58449.844
B61: 45309 | G61: Pagos Realizados | N61: -2999.88 | P61: =SUM(Table134723[[#This Row],[Valor de la Factura del Cliente]:[Avance]])+P60 -> 55449.964
B62: 45547 | G62: Pagos Realizados | N62: -18661.99 | P62: =SUM(Table134723[[#This Row],[Valor de la Factura del Cliente]:[Avance]])+P61 -> 36787.974
B63: 45548 | G63: Pagos Realizados | N63: -9242.78 | P63: =SUM(Table134723[[#This Row],[Valor de la Factura del Cliente]:[Avance]])+P62 -> 27545.194
B64: 45806 | G64: Pagos Realizados | N64: -11873.59 | P64: =SUM(Table134723[[#This Row],[Valor de la Factura del Cliente]:[Avance]])+P63 -> 15671.604
B65: 45930 | G65: Pagos Realizados | N65: -9000 | P65: =SUM(Table134723[[#This Row],[Valor de la Factura del Cliente]:[Avance]])+P64 -> 6671.6043
G66: TOTAL | H66: =SUBTOTAL(109,Table134723[Valor de la Factura del Cliente]) -> 84204.697 | I66: =SUBTOTAL(109,Table134723[Cargos Bancarios]) -> 0 | K66: =SUBTOTAL(109,Table134723[10% Comisión]) -> -5482.799 | L66: =SUBTOTAL(109,Table134723[5% Legal]) -> 0 | M66: =SUBTOTAL(109,Table134723[Retención de Impuestos]) -> 0 | N66: =SUBTOTAL(109,Table134723[Pagado por MVPX]) -> -57361.94 | O66: =SUBTOTAL(109,Table134723[Avance]) -> 0 | P66: =+P65 -> 6671.6043

Sheet LANALIZER
B2: Artista: | E2: LANALIZER
B3: Nombre legal: | E3: =+'Base de datos'!E17 -> Yan Carlo Francisco Guzmán Velásquez
B4: Fecha de inicio: | E4: =MIN(Table134721[Fecha]) -> 43872
B5: Fecha fin: | E5: =MAX(Table134721[Fecha]) -> 45861
B7: ESTADO DE CUENTA
B8: Fecha | C8: Número | D8: Tipo | E8: Método de pago | F8: Nombre | G8: Concepto | H8: Valor de la Factura del Cliente | I8: Cargos Bancarios | J8: 50% Fee | K8: 20% Comisión | L8: 5% Legal | M8: Retención de Impuestos | N8: Pagado por MVPX | O8: Avance | P8: Balance
G9: Ganga | H9: 3418.2 | P9: =SUM(Table134721[[#This Row],[Valor de la Factura del Cliente]:[Avance]]) -> 3418.2
B10: 44309 | G10: Production Services for Maikel De la Calle & Lennis Rodriguez"Secreto" | H10: 4839.6 | K10: =-Table134721[[#This Row],[Valor de la Factura del Cliente]]*0.2 -> -967.92 | L10: =-Table134721[[#This Row],[Valor de la Factura del Cliente]]*0.05 -> -241.98 | P10: =SUM(Table134721[[#This Row],[Valor de la Factura del Cliente]:[Avance]])+P9 -> 7047.9
B11: 44127 | G11: Brytiago - Condena y Crush | H11: 3000 | K11: =-Table134721[[#This Row],[Valor de la Factura del Cliente]]*0.2 -> -600 | L11: =-Table134721[[#This Row],[Valor de la Factura del Cliente]]*0.05 -> -150 | P11: =SUM(Table134721[[#This Row],[Valor de la Factura del Cliente]:[Avance]])+P10 -> 9297.9
B12: 43872 | G12: Production Services for Ankhal new release "High Class" | H12: 2000 | K12: =-Table134721[[#This Row],[Valor de la Factura del Cliente]]*0.2 -> -400 | L12: =-Table134721[[#This Row],[Valor de la Factura del Cliente]]*0.05 -> -100 | P12: =SUM(Table134721[[#This Row],[Valor de la Factura del Cliente]:[Avance]])+P11 -> 10797.9
B13: 44055 | G13: Production services for Ankhal new release "FRESHY" | H13: 2500 | K13: =-Table134721[[#This Row],[Valor de la Factura del Cliente]]*0.2 -> -500 | L13: =-Table134721[[#This Row],[Valor de la Factura del Cliente]]*0.05 -> -125 | P13: =SUM(Table134721[[#This Row],[Valor de la Factura del Cliente]:[Avance]])+P12 -> 12672.9
B14: 44049 | G14: Production services for single "Mi Carta" by Beele | H14: 4000 | K14: =-Table134721[[#This Row],[Valor de la Factura del Cliente]]*0.2 -> -800 | L14: =-Table134721[[#This Row],[Valor de la Factura del Cliente]]*0.05 -> -200 | P14: =SUM(Table134721[[#This Row],[Valor de la Factura del Cliente]:[Avance]])+P13 -> 15672.9
B15: 45397 | G15: Lanalizer Deal | H15: 4000 | K15: =-Table134721[[#This Row],[Valor de la Factura del Cliente]]*0.2 -> -800 | L15: =-Table134721[[#This Row],[Valor de la Factura del Cliente]]*0.05 -> -200 | P15: =SUM(Table134721[[#This Row],[Valor de la Factura del Cliente]:[Avance]])+P14 -> 18672.9
B16: 45751 | G16: Under Water Music LLC - Porducción de tema Quikie para Deivi | H16: 2000 | K16: =-Table134721[[#This Row],[Valor de la Factura del Cliente]]*0.2 -> -400 | L16: =-Table134721[[#This Row],[Valor de la Factura del Cliente]]*0.05 -> -100 | P16: =SUM(Table134721[[#This Row],[Valor de la Factura del Cliente]:[Avance]])+P15 -> 20172.9
B17: Q32020 | G17: Reporte de Regalías de Ejecucion Publica | H17: 0 | J17: =-Table134721[[#This Row],[Valor de la Factura del Cliente]]*0.5 -> 0 | P17: =SUM(Table134721[[#This Row],[Valor de la Factura del Cliente]:[Avance]])+P16 -> 20172.9
B18: Q42020 | G18: Reporte de Regalías de Ejecucion Publica | H18: 0 | J18: =-Table134721[[#This Row],[Valor de la Factura del Cliente]]*0.5 -> 0 | P18: =SUM(Table134721[[#This Row],[Valor de la Factura del Cliente]:[Avance]])+P17 -> 20172.9
